Workbook
Name Slicer_Platform: #N/A
Name Slicer_Platform1: #N/A

Sheet Hashtag
A1: Post ID | B1: Platform | C1: Date | D1: Content Type | E1: Post Text | F1: Likes | G1: Shares | H1: Comments | I1: Impressions | J1: Reach | K1: Clicks | L1: Engagement Rate | M1: Hashtags Used | N1: Campaign_Name
A2: P001 | B2: Twitter | C2: 45649 | D2: Reel | E2: Check out our latest reel on twitter! | F2: 1461 | G2: 184 | H2: 344 | I2: 21915 | J2: 21675 | K2: 15 | L2: =(Posts[[#This Row],[Likes]]+Posts[[#This Row],[Shares]]+Posts[[#This Row],[Comments]])/Posts[[#This Row],[Impressions]] -> 0.090759754 | M2: #FutureOfDriving | N2: CybertruckLaunch
A3: P001 | B3: Twitter | C3: 45649 | D3: Reel | E3: Check out our latest reel on twitter! | F3: 1461 | G3: 184 | H3: 344 | I3: 21915 | J3: 21675 | K3: 15 | L3: =(Posts[[#This Row],[Likes]]+Posts[[#This Row],[Shares]]+Posts[[#This Row],[Comments]])/Posts[[#This Row],[Impressions]] -> 0.090759754 | M3: #AnytimeIsTeslaTime | N3: CybertruckLaunch
A4: P002 | B4: Twitter | C4: 45750 | D4: Text | E4: Check out our latest text on twitter! | F4: 4054 | G4: 389 | H4: 493 | I4: 64864 | J4: 64383 | K4: 117 | L4: =(Posts[[#This Row],[Likes]]+Posts[[#This Row],[Shares]]+Posts[[#This Row],[Comments]])/Posts[[#This Row],[Impressions]] -> 0.076097681 | M4: #TeslaCoInnovation | N4: ModelYCampaign
A5: P002 | B5: Twitter | C5: 45750 | D5: Text | E5: Check out our latest text on twitter! | F5: 4054 | G5: 389 | H5: 493 | I5: 64864 | J5: 64383 | K5: 117 | L5: =(Posts[[#This Row],[Likes]]+Posts[[#This Row],[Shares]]+Posts[[#This Row],[Comments]])/Posts[[#This Row],[Impressions]] -> 0.076097681 | M5: #BetterWithTesla | N5: ModelYCampaign
A6: P003 | B6: YouTube | C6: 45789 | D6: Reel | E6: Check out our latest reel on youtube! | F6: 2795 | G6: 105 | H6: 49 | I6: 53105 | J6: 52307 | K6: 204 | L6: =(Posts[[#This Row],[Likes]]+Posts[[#This Row],[Shares]]+Posts[[#This Row],[Comments]])/Posts[[#This Row],[Impressions]] -> 0.055531494 | M6: #TeslaCoInnovation | N6: FSDUpdate
A7: P004 | B7: Instagram | C7: 45516 | D7: Story | E7: Check out our latest story on instagram! | F7: 2404 | G7: 363 | H7: 138 | I7: 19232 | J7: 18636 | K7: 128 | L7: =(Posts[[#This Row],[Likes]]+Posts[[#This Row],[Shares]]+Posts[[#This Row],[Comments]])/Posts[[#This Row],[Impressions]] -> 0.15105033 | M7: #EVRevolution | N7: SustainabilityDrive
A8: P005 | B8: YouTube | C8: 45469 | D8: Reel | E8: Check out our latest reel on youtube! | F8: 3557 | G8: 687 | H8: 424 | I8: 71140 | J8: 70701 | K8: 224 | L8: =(Posts[[#This Row],[Likes]]+Posts[[#This Row],[Shares]]+Posts[[#This Row],[Comments]])/Posts[[#This Row],[Impressions]] -> 0.065617093 | M8: #EVRevolution | N8: CybertruckLaunch
A9: P005 | B9: YouTube | C9: 45469 | D9: Reel | E9: Check out our latest reel on youtube! | F9: 3557 | G9: 687 | H9: 424 | I9: 71140 | J9: 70701 | K9: 224 | L9: =(Posts[[#This Row],[Likes]]+Posts[[#This Row],[Shares]]+Posts[[#This Row],[Comments]])/Posts[[#This Row],[Impressions]] -> 0.065617093 | M9: #TeslaCoInnovation | N9: CybertruckLaunch
A10: P006 | B10: Facebook | C10: 45596 | D10: Carousel | E10: Check out our latest carousel on facebook! | F10: 2945 | G10: 930 | H10: 355 | I10: 23560 | J10: 23275 | K10: 256 | L10: =(Posts[[#This Row],[Likes]]+Posts[[#This Row],[Shares]]+Posts[[#This Row],[Comments]])/Posts[[#This Row],[Impressions]] -> 0.1795416 | M10: #TeslaCoInnovation | N10: ModelYCampaign
A11: P007 | B11: Twitter | C11: 45467 | D11: Carousel | E11: Check out our latest carousel on twitter! | F11: 3860 | G11: 201 | H11: 279 | I11: 61760 | J11: 61660 | K11: 235 | L11: =(Posts[[#This Row],[Likes]]+Posts[[#This Row],[Shares]]+Posts[[#This Row],[Comments]])/Posts[[#This Row],[Impressions]] -> 0.070272021 | M11: #TeslaCoInnovation | N11: ModelYCampaign
A12: P008 | B12: YouTube | C12: 45486 | D12: Image | E12: Check out our latest image on youtube! | F12: 3929 | G12: 262 | H12: 278 | I12: 43219 | J12: 42841 | K12: 39 | L12: =(Posts[[#This Row],[Likes]]+Posts[[#This Row],[Shares]]+Posts[[#This Row],[Comments]])/Posts[[#This Row],[Impressions]] -> 0.1034036 | M12: #EVRevolution | N12: SustainabilityDrive
A13: P009 | B13: Facebook | C13: 45534 | D13: Text | E13: Check out our latest text on facebook! | F13: 3784 | G13: 808 | H13: 404 | I13: 56760 | J13: 56343 | K13: 131 | L13: =(Posts[[#This Row],[Likes]]+Posts[[#This Row],[Shares]]+Posts[[#This Row],[Comments]])/Posts[[#This Row],[Impressions]] -> 0.088019732 | M13: #TeslaCoInnovation | N13: ModelYCampaign
... A17: P013 | B17: YouTube | C17: 45614 | D17: Carousel | E17: Check out our latest carousel on youtube! | F17: 1171 | G17: 286 | H17: 231 | I17: 22249 | J17: 21282 | K17: 114 | L17: =(Posts[[#This Row],[Likes]]+Posts[[#This Row],[Shares]]+Posts[[#This Row],[Comments]])/Posts[[#This Row],[Impressions]] -> 0.075868578 | M17: #EVRevolution | N17: CybertruckLaunch
A18: P014 | B18: Facebook | C18: 45704 | D18: Story | E18: Check out our latest story on facebook! | F18: 4242 | G18: 555 | H18: 131 | I18: 33936 | J18: 33802 | K18: 265 | L18: =(Posts[[#This Row],[Likes]]+Posts[[#This Row],[Shares]]+Posts[[#This Row],[Comments]])/Posts[[#This Row],[Impressions]] -> 0.14521452 | M18: #FutureOfDriving
A19: P015 | B19: Facebook | C19: 45589 | D19: Video | E19: Check out our latest video on facebook! | F19: 3888 | G19: 604 | H19: 128 | I19: 77760 | J19: 77167 | K19: 20 | L19: =(Posts[[#This Row],[Likes]]+Posts[[#This Row],[Shares]]+Posts[[#This Row],[Comments]])/Posts[[#This Row],[Impressions]] -> 0.05941358 | M19: #FutureOfDriving | N19: CybertruckLaunch
A20: P016 | B20: Facebook | C20: 45530 | D20: Text | E20: Check out our latest text on facebook! | F20: 3452 | G20: 377 | H20: 360 | I20: 55232 | J20: 55075 | K20: 87 | L20: =(Posts[[#This Row],[Likes]]+Posts[[#This Row],[Shares]]+Posts[[#This Row],[Comments]])/Posts[[#This Row],[Impressions]] -> 0.075843714 | M20: #FutureOfDriving | N20: FSDUpdate
A21: P017 | B21: Facebook | C21: 45782 | D21: Text | E21: Check out our latest text on facebook! | F21: 4441 | G21: 511 | H21: 70 | I21: 53292 | J21: 53082 | K21: 159 | L21: =(Posts[[#This Row],[Likes]]+Posts[[#This Row],[Shares]]+Posts[[#This Row],[Comments]])/Posts[[#This Row],[Impressions]] -> 0.094235533 | M21: #EVRevolution | N21: SustainabilityDrive
A22: P018 | B22: Instagram | C22: 45523 | D22: Reel | E22: Check out our latest reel on instagram! | F22: 3000 | G22: 382 | H22: 325 | I22: 36000 | J22: 35819 | K22: 19 | L22: =(Posts[[#This Row],[Likes]]+Posts[[#This Row],[Shares]]+Posts[[#This Row],[Comments]])/Posts[[#This Row],[Impressions]] -> 0.10297222 | M22: #FutureOfDriving | N22: CybertruckLaunch
A23: P019 | B23: Instagram | C23: 45466 | D23: Video | E23: Check out our latest video on instagram! | F23: 1071 | G23: 519 | H23: 22 | I23: 16065 | J23: 15865 | K23: 103 | L23: =(Posts[[#This Row],[Likes]]+Posts[[#This Row],[Shares]]+Posts[[#This Row],[Comments]])/Posts[[#This Row],[Impressions]] -> 0.10034236 | M23: #TeslaCoInnovation | N23: SustainabilityDrive
A24: P020 | B24: Instagram | C24: 45544 | D24: Carousel | E24: Check out our latest carousel on instagram! | F24: 4054 | G24: 488 | H24: 373 | I24: 77026 | J24: 76881 | K24: 25 | L24: =(Posts[[#This Row],[Likes]]+Posts[[#This Row],[Shares]]+Posts[[#This Row],[Comments]])/Posts[[#This Row],[Impressions]] -> 0.063809623 | M24: #TeslaCoInnovation | N24: CybertruckLaunch
A25: P021 | B25: Instagram | C25: 45661 | D25: Reel | E25: Check out our latest reel on instagram! | F25: 4838 | G25: 640 | H25: 128 | I25: 72570 | J25: 72396 | K25: 83 | L25: =(Posts[[#This Row],[Likes]]+Posts[[#This Row],[Shares]]+Posts[[#This Row],[Comments]])/Posts[[#This Row],[Impressions]] -> 0.077249552 | M25: #FutureOfDriving | N25: SustainabilityDrive
A26: P022 | B26: Facebook | C26: 45715 | D26: Text | E26: Check out our latest text on facebook! | F26: 1570 | G26: 187 | H26: 260 | I26: 25120 | J26: 24613 | K26: 133 | L26: =(Posts[[#This Row],[Likes]]+Posts[[#This Row],[Shares]]+Posts[[#This Row],[Comments]])/Posts[[#This Row],[Impressions]] -> 0.080294586 | M26: #TeslaCoInnovation | N26: SustainabilityDrive
A27: P023 | B27: Facebook | C27: 45602 | D27: Video | E27: Check out our latest video on facebook! | F27: 1606 | G27: 547 | H27: 316 | I27: 32120 | J27: 31736 | K27: 225 | L27: =(Posts[[#This Row],[Likes]]+Posts[[#This Row],[Shares]]+Posts[[#This Row],[Comments]])/Posts[[#This Row],[Impressions]] -> 0.076867995 | M27: #TeslaCoInnovation | N27: ModelYCampaign
A28: P023 | B28: Facebook | C28: 45602 | D28: Video | E28: Check out our latest video on facebook! | F28: 1606 | G28: 547 | H28: 316 | I28: 32120 | J28: 31736 | K28: 225 | L28: =(Posts[[#This Row],[Likes]]+Posts[[#This Row],[Shares]]+Posts[[#This Row],[Comments]])/Posts[[#This Row],[Impressions]] -> 0.076867995 | M28: #AnytimeIsTeslaTime | N28: ModelYCampaign
A29: P024 | B29: Facebook | C29: 45680 | D29: Video | E29: Check out our latest video on facebook! | F29: 3961 | G29: 761 | H29: 131 | I29: 67337 | J29: 66615 | K29: 161 | L29: =(Posts[[#This Row],[Likes]]+Posts[[#This Row],[Shares]]+Posts[[#This Row],[Comments]])/Posts[[#This Row],[Impressions]] -> 0.072070333 | M29: #FutureOfDriving | N29: FSDUpdate
A30: P025 | B30: Twitter | C30: 45757 | D30: Carousel | E30: Check out our latest carousel on twitter! | F30: 3128 | G30: 211 | H30: 197 | I30: 59432 | J30: 59182 | K30: 238 | L30: =(Posts[[#This Row],[Likes]]+Posts[[#This Row],[Shares]]+Posts[[#This Row],[Comments]])/Posts[[#This Row],[Impressions]] -> 0.059496568 | M30: #EVRevolution
A31: P026 | B31: YouTube | C31: 45752 | D31: Reel | E31: Check out our latest reel on youtube! | F31: 3009 | G31: 413 | H31: 358 | I31: 42126 | J31: 41309 | K31: 211 | L31: =(Posts[[#This Row],[Likes]]+Posts[[#This Row],[Shares]]+Posts[[#This Row],[Comments]])/Posts[[#This Row],[Impressions]] -> 0.089730808 | M31: #FutureOfDriving | N31: ModelYCampaign
A32: P027 | B32: YouTube | C32: 45552 | D32: Text | E32: Check out our latest text on youtube! | F32: 2076 | G32: 195 | H32: 104 | I32: 33216 | J32: 32244 | K32: 51 | L32: =(Posts[[#This Row],[Likes]]+Posts[[#This Row],[Shares]]+Posts[[#This Row],[Comments]])/Posts[[#This Row],[Impressions]] -> 0.071501686 | M32: #FutureOfDriving | N32: SustainabilityDrive
A33: P028 | B33: Instagram | C33: 45720 | D33: Video | E33: Check out our latest video on instagram! | F33: 432 | G33: 624 | H33: 123 | I33: 6912 | J33: 6259 | K33: 79 | L33: =(Posts[[#This Row],[Likes]]+Posts[[#This Row],[Shares]]+Posts[[#This Row],[Comments]])/Posts[[#This Row],[Impressions]] -> 0.17057292 | M33: #FutureOfDriving | N33: SustainabilityDrive
A34: P029 | B34: Instagram | C34: 45688 | D34: Carousel | E34: Check out our latest carousel on instagram! | F34: 2566 | G34: 118 | H34: 37 | I34: 12830 | J34: 12264 | K34: 221 | L34: =(Posts[[#This Row],[Likes]]+Posts[[#This Row],[Shares]]+Posts[[#This Row],[Comments]])/Posts[[#This Row],[Impressions]] -> 0.21208106 | M34: #FutureOfDriving | N34: FSDUpdate
A35: P030 | B35: Instagram | C35: 45713 | D35: Video | E35: Check out our latest video on instagram! | F35: 3095 | G35: 39 | H35: 78 | I35: 55710 | J35: 54808 | K35: 93 | L35: =(Posts[[#This Row],[Likes]]+Posts[[#This Row],[Shares]]+Posts[[#This Row],[Comments]])/Posts[[#This Row],[Impressions]] -> 0.057655717 | M35: #EVRevolution
A36: P031 | B36: Instagram | C36: 45642 | D36: Text | E36: Check out our latest text on instagram! | F36: 438 | G36: 153 | H36: 275 | I36: 3066 | J36: 2701 | K36: 282 | L36: =(Posts[[#This Row],[Likes]]+Posts[[#This Row],[Shares]]+Posts[[#This Row],[Comments]])/Posts[[#This Row],[Impressions]] -> 0.28245271 | M36: #TeslaCoInnovation | N36: ModelYCampaign
A37: P032 | B37: Twitter | C37: 45504 | D37: Carousel | E37: Check out our latest carousel on twitter! | F37: 2278 | G37: 10 | H37: 321 | I37: 13668 | J37: 12676 | K37: 275 | L37: =(Posts[[#This Row],[Likes]]+Posts[[#This Row],[Shares]]+Posts[[#This Row],[Comments]])/Posts[[#This Row],[Impressions]] -> 0.19088382 | M37: #EVRevolution | N37: CybertruckLaunch
A38: P033 | B38: Facebook | C38: 45525 | D38: Image | E38: Check out our latest image on facebook! | F38: 1407 | G38: 400 | H38: 351 | I38: 16884 | J38: 15954 | K38: 113 | L38: =(Posts[[#This Row],[Likes]]+Posts[[#This Row],[Shares]]+Posts[[#This Row],[Comments]])/Posts[[#This Row],[Impressions]] -> 0.12781331 | M38: #TeslaCoInnovation | N38: CybertruckLaunch
A39: P034 | B39: Facebook | C39: 45742 | D39: Text | E39: Check out our latest text on facebook! | F39: 1652 | G39: 89 | H39: 357 | I39: 29736 | J39: 28771 | K39: 215 | L39: =(Posts[[#This Row],[Likes]]+Posts[[#This Row],[Shares]]+Posts[[#This Row],[Comments]])/Posts[[#This Row],[Impressions]] -> 0.07055421 | M39: #TeslaCoInnovation | N39: FSDUpdate
A40: P035 | B40: Instagram | C40: 45626 | D40: Video | E40: Check out our latest video on instagram! | F40: 3775 | G40: 16 | H40: 239 | I40: 33975 | J40: 33310 | K40: 271 | L40: =(Posts[[#This Row],[Likes]]+Posts[[#This Row],[Shares]]+Posts[[#This Row],[Comments]])/Posts[[#This Row],[Impressions]] -> 0.11861663 | M40: #FutureOfDriving | N40: ModelYCampaign
A41: P036 | B41: Instagram | C41: 45766 | D41: Story | E41: Check out our latest story on instagram! | F41: 4518 | G41: 285 | H41: 383 | I41: 67770 | J41: 67621 | K41: 31 | L41: =(Posts[[#This Row],[Likes]]+Posts[[#This Row],[Shares]]+Posts[[#This Row],[Comments]])/Posts[[#This Row],[Impressions]] -> 0.076523535 | M41: #EVRevolution | N41: ModelYCampaign
A42: P037 | B42: Facebook | C42: 45663 | D42: Carousel | E42: Check out our latest carousel on facebook! | F42: 3024 | G42: 925 | H42: 350 | I42: 24192 | J42: 23518 | K42: 36 | L42: =(Posts[[#This Row],[Likes]]+Posts[[#This Row],[Shares]]+Posts[[#This Row],[Comments]])/Posts[[#This Row],[Impressions]] -> 0.17770337 | M42: #EVRevolution | N42: ModelYCampaign
A43: P038 | B43: YouTube | C43: 45705 | D43: Reel | E43: Check out our latest reel on youtube! | F43: 3138 | G43: 123 | H43: 291 | I43: 28242 | J43: 27550 | K43: 87 | L43: =(Posts[[#This Row],[Likes]]+Posts[[#This Row],[Shares]]+Posts[[#This Row],[Comments]])/Posts[[#This Row],[Impressions]] -> 0.12577013 | M43: #TeslaCoInnovation | N43: SustainabilityDrive
...

Sheet Posts (2)
A1: Post ID | B1: Platform | C1: Date | D1: Content Type | E1: Post Text | F1: Likes | G1: Shares | H1: Comments | I1: Impressions | J1: Reach | K1: Clicks | L1: Engagement Rate | M1: Hashtags Used | N1: Campaign_Name
A2: P220 | B2: Instagram | C2: 45445 | D2: Story | E2: Check out our latest story on instagram! | F2: 84 | G2: 897 | H2: 85 | I2: 588 | J2: 8 | K2: 12 | L2: =(F2+G2+H2)/I2 -> 1.8129252 | M2: #EVRevolution
A3: P058 | B3: Instagram | C3: 45762 | D3: Reel | E3: Check out our latest reel on instagram! | F3: 103 | G3: 770 | H3: 19 | I3: 1030 | J3: 410 | K3: 262 | L3: =(F3+G3+H3)/I3 -> 0.86601942 | M3: #TeslaCoInnovation | N3: SustainabilityDrive
A4: P232 | B4: Twitter | C4: 45776 | D4: Story | E4: Check out our latest story on twitter! | F4: 249 | G4: 592 | H4: 230 | I4: 1494 | J4: 1044 | K4: 201 | L4: =(F4+G4+H4)/I4 -> 0.71686747 | M4: #EVRevolution | N4: SustainabilityDrive
A5: P178 | B5: Instagram | C5: 45603 | D5: Video | E5: Check out our latest video on instagram! | F5: 129 | G5: 643 | H5: 136 | I5: 1290 | J5: 839 | K5: 238 | L5: =(F5+G5+H5)/I5 -> 0.70387597 | M5: #TeslaCoInnovation | N5: SustainabilityDrive
A6: P175 | B6: Instagram | C6: 45674 | D6: Reel | E6: Check out our latest reel on instagram! | F6: 142 | G6: 784 | H6: 183 | I6: 1704 | J6: 995 | K6: 154 | L6: =(F6+G6+H6)/I6 -> 0.6508216 | M6: #FutureOfDriving | N6: SustainabilityDrive
A7: P062 | B7: Twitter | C7: 45618 | D7: Carousel | E7: Check out our latest carousel on twitter! | F7: 53 | G7: 81 | H7: 379 | I7: 954 | J7: 7 | K7: 148 | L7: =(F7+G7+H7)/I7 -> 0.53773585 | M7: #TeslaCoInnovation | N7: FSDUpdate
A8: P264 | B8: Twitter | C8: 45687 | D8: Image | E8: Check out our latest image on twitter! | F8: 59 | G8: 163 | H8: 93 | I8: 590 | J8: 475 | K8: 293 | L8: =(F8+G8+H8)/I8 -> 0.53389831 | M8: #TeslaCoInnovation | N8: ModelYCampaign
A9: P143 | B9: YouTube | C9: 45567 | D9: Carousel | E9: Check out our latest carousel on youtube! | F9: 80 | G9: 362 | H9: 80 | I9: 1040 | J9: 349 | K9: 117 | L9: =(F9+G9+H9)/I9 -> 0.50192308 | M9: #TeslaCoInnovation | N9: FSDUpdate
A10: P210 | B10: YouTube | C10: 45707 | D10: Image | E10: Check out our latest image on youtube! | F10: 257 | G10: 966 | H10: 398 | I10: 3341 | J10: 2753 | K10: 287 | L10: =(F10+G10+H10)/I10 -> 0.48518408 | M10: #FutureOfDriving | N10: CybertruckLaunch
A11: P070 | B11: Facebook | C11: 45749 | D11: Video | E11: Check out our latest video on facebook! | F11: 199 | G11: 772 | H11: 400 | I11: 3582 | J11: 2988 | K11: 43 | L11: =(F11+G11+H11)/I11 -> 0.38274707 | M11: #TeslaCoInnovation
A12: P214 | B12: Instagram | C12: 45649 | D12: Image | E12: Check out our latest image on instagram! | F12: 521 | G12: 746 | H12: 315 | I12: 4168 | J12: 3399 | K12: 282 | L12: =(F12+G12+H12)/I12 -> 0.37955854 | M12: #FutureOfDriving | N12: ModelYCampaign
A13: P053 | B13: YouTube | C13: 45712 | D13: Carousel | E13: Check out our latest carousel on youtube! | F13: 804 | G13: 639 | H13: 43 | I13: 4020 | J13: 3144 | K13: 11 | L13: =(F13+G13+H13)/I13 -> 0.36965174 | M13: #EVRevolution,#BetterWithTesla
A14: P102 | B14: Twitter | C14: 45553 | D14: Reel | E14: Check out our latest reel on twitter! | F14: 1000 | G14: 978 | H14: 162 | I14: 6000 | J14: 5221 | K14: 223 | L14: =(F14+G14+H14)/I14 -> 0.35666667 | M14: #EVRevolution | N14: ModelYCampaign
A15: P124 | B15: YouTube | C15: 45753 | D15: Carousel | E15: Check out our latest carousel on youtube! | F15: 736 | G15: 771 | H15: 225 | I15: 5152 | J15: 4706 | K15: 19 | L15: =(F15+G15+H15)/I15 -> 0.33618012 | M15: #EVRevolution | N15: CybertruckLaunch
A16: P121 | B16: Instagram | C16: 45502 | D16: Story | E16: Check out our latest story on instagram! | F16: 498 | G16: 701 | H16: 412 | I16: 4980 | J16: 4185 | K16: 185 | L16: =(F16+G16+H16)/I16 -> 0.32349398 | M16: #FutureOfDriving
A17: P224 | B17: Facebook | C17: 45790 | D17: Image | E17: Check out our latest image on facebook! | F17: 602 | G17: 594 | H17: 156 | I17: 4214 | J17: 3363 | K17: 164 | L17: =(F17+G17+H17)/I17 -> 0.32083531 | M17: #TeslaCoInnovation | N17: FSDUpdate
A18: P154 | B18: Instagram | C18: 45574 | D18: Carousel | E18: Check out our latest carousel on instagram! | F18: 985 | G18: 932 | H18: 287 | I18: 6895 | J18: 6757 | K18: 64 | L18: =(F18+G18+H18)/I18 -> 0.31965192 | M18: #FutureOfDriving | N18: SustainabilityDrive
A19: P119 | B19: Instagram | C19: 45695 | D19: Reel | E19: Check out our latest reel on instagram! | F19: 1970 | G19: 675 | H19: 478 | I19: 9850 | J19: 8924 | K19: 117 | L19: =(F19+G19+H19)/I19 -> 0.31705584 | M19: #FutureOfDriving
A20: P287 | B20: Instagram | C20: 45519 | D20: Reel | E20: Check out our latest reel on instagram! | F20: 1164 | G20: 616 | H20: 324 | I20: 6984 | J20: 6636 | K20: 82 | L20: =(F20+G20+H20)/I20 -> 0.30126002 | M20: #EVRevolution | N20: CybertruckLaunch
A21: P204 | B21: Instagram | C21: 45658 | D21: Carousel | E21: Check out our latest carousel on instagram! | F21: 2234 | G21: 653 | H21: 432 | I21: 11170 | J21: 10569 | K21: 198 | L21: =(F21+G21+H21)/I21 -> 0.29713518 | M21: #FutureOfDriving | N21: FSDUpdate
A22: P066 | B22: Twitter | C22: 45499 | D22: Carousel | E22: Check out our latest carousel on twitter! | F22: 432 | G22: 171 | H22: 280 | I22: 3024 | J22: 2285 | K22: 184 | L22: =(F22+G22+H22)/I22 -> 0.29199735 | M22: #EVRevolution | N22: CybertruckLaunch
A23: P183 | B23: Instagram | C23: 45643 | D23: Story | E23: Check out our latest story on instagram! | F23: 360 | G23: 590 | H23: 393 | I23: 4680 | J23: 4322 | K23: 208 | L23: =(F23+G23+H23)/I23 -> 0.28696581 | M23: #FutureOfDriving | N23: ModelYCampaign
A24: P031 | B24: Instagram | C24: 45642 | D24: Text | E24: Check out our latest text on instagram! | F24: 438 | G24: 153 | H24: 275 | I24: 3066 | J24: 2701 | K24: 282 | L24: =(F24+G24+H24)/I24 -> 0.28245271 | M24: #TeslaCoInnovation | N24: ModelYCampaign
A25: P093 | B25: Instagram | C25: 45637 | D25: Video | E25: Check out our latest video on instagram! | F25: 1431 | G25: 951 | H25: 26 | I25: 8586 | J25: 8396 | K25: 150 | L25: =(F25+G25+H25)/I25 -> 0.28045656 | M25: #EVRevolution | N25: FSDUpdate
A26: P263 | B26: Instagram | C26: 45524 | D26: Reel | E26: Check out our latest reel on instagram! | F26: 2603 | G26: 690 | H26: 205 | I26: 13015 | J26: 12130 | K26: 20 | L26: =(F26+G26+H26)/I26 -> 0.26876681 | M26: #FutureOfDriving | N26: ModelYCampaign
A27: P248 | B27: Facebook | C27: 45690 | D27: Story | E27: Check out our latest story on facebook! | F27: 886 | G27: 126 | H27: 153 | I27: 4430 | J27: 4037 | K27: 212 | L27: =(F27+G27+H27)/I27 -> 0.26297968 | M27: #EVRevolution
A28: P244 | B28: YouTube | C28: 45590 | D28: Video | E28: Check out our latest video on youtube! | F28: 4661 | G28: 935 | H28: 433 | I28: 23305 | J28: 22583 | K28: 63 | L28: =(F28+G28+H28)/I28 -> 0.25869985 | M28: #FutureOfDriving | N28: FSDUpdate
A29: P259 | B29: Facebook | C29: 45698 | D29: Text | E29: Check out our latest text on facebook! | F29: 562 | G29: 158 | H29: 149 | I29: 3372 | J29: 2940 | K29: 93 | L29: =(F29+G29+H29)/I29 -> 0.25771056 | M29: #TeslaCoInnovation | N29: CybertruckLaunch
A30: P219 | B30: Twitter | C30: 45685 | D30: Reel | E30: Check out our latest reel on twitter! | F30: 1188 | G30: 470 | H30: 174 | I30: 7128 | J30: 6145 | K30: 270 | L30: =(F30+G30+H30)/I30 -> 0.25701459 | M30: #TeslaCoInnovation | N30: SustainabilityDrive
A31: P226 | B31: Instagram | C31: 45511 | D31: Carousel | E31: Check out our latest carousel on instagram! | F31: 1741 | G31: 164 | H31: 318 | I31: 8705 | J31: 8272 | K31: 121 | L31: =(F31+G31+H31)/I31 -> 0.25537048 | M31: #TeslaCoInnovation
A32: P265 | B32: Twitter | C32: 45708 | D32: Carousel | E32: Check out our latest carousel on twitter! | F32: 1877 | G32: 745 | H32: 225 | I32: 11262 | J32: 10967 | K32: 41 | L32: =(F32+G32+H32)/I32 -> 0.25279702 | M32: #EVRevolution | N32: SustainabilityDrive
A33: P239 | B33: YouTube | C33: 45712 | D33: Text | E33: Check out our latest text on youtube! | F33: 4188 | G33: 942 | H33: 118 | I33: 20940 | J33: 20471 | K33: 102 | L33: =(F33+G33+H33)/I33 -> 0.25062082 | M33: #FutureOfDriving
A34: P277 | B34: Facebook | C34: 45753 | D34: Image | E34: Check out our latest image on facebook! | F34: 4236 | G34: 711 | H34: 298 | I34: 21180 | J34: 20516 | K34: 238 | L34: =(F34+G34+H34)/I34 -> 0.24763928 | M34: #FutureOfDriving | N34: CybertruckLaunch
A35: P297 | B35: Twitter | C35: 45650 | D35: Text | E35: Check out our latest text on twitter! | F35: 2166 | G35: 354 | H35: 117 | I35: 10830 | J35: 10245 | K35: 24 | L35: =(F35+G35+H35)/I35 -> 0.2434903 | M35: #EVRevolution | N35: SustainabilityDrive
A36: P181 | B36: YouTube | C36: 45737 | D36: Image | E36: Check out our latest image on youtube! | F36: 606 | G36: 789 | H36: 470 | I36: 7878 | J36: 7389 | K36: 239 | L36: =(F36+G36+H36)/I36 -> 0.23673521 | M36: #EVRevolution | N36: FSDUpdate
A37: P246 | B37: Facebook | C37: 45576 | D37: Image | E37: Check out our latest image on facebook! | F37: 400 | G37: 680 | H37: 434 | I37: 6400 | J37: 5472 | K37: 160 | L37: =(F37+G37+H37)/I37 -> 0.2365625 | M37: #FutureOfDriving | N37: ModelYCampaign
A38: P123 | B38: Instagram | C38: 45457 | D38: Story | E38: Check out our latest story on instagram! | F38: 4363 | G38: 649 | H38: 140 | I38: 21815 | J38: 21481 | K38: 157 | L38: =(F38+G38+H38)/I38 -> 0.23616777 | M38: #EVRevolution | N38: CybertruckLaunch
A39: P120 | B39: Facebook | C39: 45586 | D39: Story | E39: Check out our latest story on facebook! | F39: 780 | G39: 928 | H39: 301 | I39: 8580 | J39: 8081 | K39: 91 | L39: =(F39+G39+H39)/I39 -> 0.23414918 | M39: #EVRevolution | N39: FSDUpdate
A40: P141 | B40: Twitter | C40: 45535 | D40: Image | E40: Check out our latest image on twitter! | F40: 3170 | G40: 857 | H40: 379 | I40: 19020 | J40: 18559 | K40: 240 | L40: =(F40+G40+H40)/I40 -> 0.23165089 | M40: #FutureOfDriving
...

Sheet Engagement Summary
A1: Week_Start_Date | B1: Platform | C1: New_Followers | D1: Unfollows | E1: Total_Followers | F1: Engagement_Rate | G1: Ad_Spend | H1: Campaign | I1: Follower Growth
A2: 45446 | B2: Facebook | C2: 1312 | D2: 310 | E2: 42654 | F2: 4.98 | G2: 9566 | H2: {=_xlfn.IFS(A2<'Campaign Metadata'!$B$2,"Before CybertruckLaunch",'Engagement Summary'!A3<='Campaign Metadata'!$C$2,"CybertruckLaunch",A2<'Campaign Metadata'!$B$3,"Before ModelYCampaign",A2<='Campaign Metadata'!$C$3,"ModelYCampaign",A2<'Campaign Metadata'!$B$4,"Before FSDUpdate",A2<='Campaign Metadata'!$C$4,FSDUpdate,A2<'Campaign Metadata'!$B$5,Before SustainabilityDrive,A2<'Campaign Metadata'!$C$5,"Sustainability Drive")} -> Before CybertruckLaunch | I2: =C2-D2 -> 1002
A3: 45453 | B3: Facebook | C3: 1697 | D3: 414 | E3: 316555 | F3: 2.37 | G3: 7924 | H3: {=_xlfn.IFS(A3<'Campaign Metadata'!$B$2,"Before CybertruckLaunch",'Engagement Summary'!A7<='Campaign Metadata'!$C$2,"CybertruckLaunch",A3<'Campaign Metadata'!$B$3,"Before ModelYCampaign",A3<='Campaign Metadata'!$C$3,"ModelYCampaign",A3<'Campaign Metadata'!$B$4,"Before FSDUpdate",A3<='Campaign Metadata'!$C$4,FSDUpdate,A3<'Campaign Metadata'!$B$5,Before SustainabilityDrive,A3<'Campaign Metadata'!$C$5,"Sustainability Drive")} -> Before CybertruckLaunch | I3: =C3-D3 -> 1283
A4: 45460 | B4: Facebook | C4: 1753 | D4: 371 | E4: 169496 | F4: 8.11 | G4: 46670 | H4: {=_xlfn.IFS(A4<'Campaign Metadata'!$B$2,"Before CybertruckLaunch",'Engagement Summary'!A11<='Campaign Metadata'!$C$2,"CybertruckLaunch",A4<'Campaign Metadata'!$B$3,"Before ModelYCampaign",A4<='Campaign Metadata'!$C$3,"ModelYCampaign",A4<'Campaign Metadata'!$B$4,"Before FSDUpdate",A4<='Campaign Metadata'!$C$4,FSDUpdate,A4<'Campaign Metadata'!$B$5,Before SustainabilityDrive,A4<'Campaign Metadata'!$C$5,"Sustainability Drive")} -> Before ModelYCampaign | I4: =C4-D4 -> 1382
A5: 45467 | B5: Facebook | C5: 1779 | D5: 109 | E5: 26295 | F5: 9.12 | G5: 30635 | H5: {=_xlfn.IFS(A5<'Campaign Metadata'!$B$2,"Before CybertruckLaunch",'Engagement Summary'!A15<='Campaign Metadata'!$C$2,"CybertruckLaunch",A5<'Campaign Metadata'!$B$3,"Before ModelYCampaign",A5<='Campaign Metadata'!$C$3,"ModelYCampaign",A5<'Campaign Metadata'!$B$4,"Before FSDUpdate",A5<='Campaign Metadata'!$C$4,FSDUpdate,A5<'Campaign Metadata'!$B$5,Before SustainabilityDrive,A5<'Campaign Metadata'!$C$5,"Sustainability Drive")} -> Before ModelYCampaign | I5: =C5-D5 -> 1670
A6: 45474 | B6: Facebook | C6: 505 | D6: 441 | E6: 220020 | F6: 4.48 | G6: 42307 | H6: {=_xlfn.IFS(A6<'Campaign Metadata'!$B$2,"Before CybertruckLaunch",'Engagement Summary'!A19<='Campaign Metadata'!$C$2,"CybertruckLaunch",A6<'Campaign Metadata'!$B$3,"Before ModelYCampaign",A6<='Campaign Metadata'!$C$3,"ModelYCampaign",A6<'Campaign Metadata'!$B$4,"Before FSDUpdate",A6<='Campaign Metadata'!$C$4,FSDUpdate,A6<'Campaign Metadata'!$B$5,Before SustainabilityDrive,A6<'Campaign Metadata'!$C$5,"Sustainability Drive")} -> Before ModelYCampaign | I6: =C6-D6 -> 64
A7: 45481 | B7: Facebook | C7: 350 | D7: 41 | E7: 251694 | F7: 1.91 | G7: 38610 | H7: {=_xlfn.IFS(A7<'Campaign Metadata'!$B$2,"Before CybertruckLaunch",'Engagement Summary'!A23<='Campaign Metadata'!$C$2,"CybertruckLaunch",A7<'Campaign Metadata'!$B$3,"Before ModelYCampaign",A7<='Campaign Metadata'!$C$3,"ModelYCampaign",A7<'Campaign Metadata'!$B$4,"Before FSDUpdate",A7<='Campaign Metadata'!$C$4,FSDUpdate,A7<'Campaign Metadata'!$B$5,Before SustainabilityDrive,A7<'Campaign Metadata'!$C$5,"Sustainability Drive")} -> Before ModelYCampaign | I7: =C7-D7 -> 309
A8: 45488 | B8: Facebook | C8: 170 | D8: 334 | E8: 334626 | F8: 6.44 | G8: 43420 | H8: {=_xlfn.IFS(A8<'Campaign Metadata'!$B$2,"Before CybertruckLaunch",'Engagement Summary'!A27<='Campaign Metadata'!$C$2,"CybertruckLaunch",A8<'Campaign Metadata'!$B$3,"Before ModelYCampaign",A8<='Campaign Metadata'!$C$3,"ModelYCampaign",A8<'Campaign Metadata'!$B$4,"Before FSDUpdate",A8<='Campaign Metadata'!$C$4,FSDUpdate,A8<'Campaign Metadata'!$B$5,Before SustainabilityDrive,A8<'Campaign Metadata'!$C$5,"Sustainability Drive")} -> Before ModelYCampaign | I8: =C8-D8 -> -164
A9: 45495 | B9: Facebook | C9: 1391 | D9: 430 | E9: 295032 | F9: 7.86 | G9: 26067 | H9: {=_xlfn.IFS(A9<'Campaign Metadata'!$B$2,"Before CybertruckLaunch",'Engagement Summary'!A31<='Campaign Metadata'!$C$2,"CybertruckLaunch",A9<'Campaign Metadata'!$B$3,"Before ModelYCampaign",A9<='Campaign Metadata'!$C$3,"ModelYCampaign",A9<'Campaign Metadata'!$B$4,"Before FSDUpdate",A9<='Campaign Metadata'!$C$4,FSDUpdate,A9<'Campaign Metadata'!$B$5,Before SustainabilityDrive,A9<'Campaign Metadata'!$C$5,"Sustainability Drive")} -> Before ModelYCampaign | I9: =C9-D9 -> 961
A10: 45502 | B10: Facebook | C10: 160 | D10: 478 | E10: 435034 | F10: 7.73 | G10: 4839 | H10: {=_xlfn.IFS(A10<'Campaign Metadata'!$B$2,"Before CybertruckLaunch",'Engagement Summary'!A35<='Campaign Metadata'!$C$2,"CybertruckLaunch",A10<'Campaign Metadata'!$B$3,"Before ModelYCampaign",A10<='Campaign Metadata'!$C$3,"ModelYCampaign",A10<'Campaign Metadata'!$B$4,"Before FSDUpdate",A10<='Campaign Metadata'!$C$4,FSDUpdate,A10<'Campaign Metadata'!$B$5,Before SustainabilityDrive,A10<'Campaign Metadata'!$C$5,"Sustainability Drive")} -> Before ModelYCampaign | I10: =C10-D10 -> -318
A11: 45509 | B11: Facebook | C11: 214 | D11: 411 | E11: 125034 | F11: 6.11 | G11: 26455 | H11: {=_xlfn.IFS(A11<'Campaign Metadata'!$B$2,"Before CybertruckLaunch",'Engagement Summary'!A39<='Campaign Metadata'!$C$2,"CybertruckLaunch",A11<'Campaign Metadata'!$B$3,"Before ModelYCampaign",A11<='Campaign Metadata'!$C$3,"ModelYCampaign",A11<'Campaign Metadata'!$B$4,"Before FSDUpdate",A11<='Campaign Metadata'!$C$4,FSDUpdate,A11<'Campaign Metadata'!$B$5,Before SustainabilityDrive,A11<'Campaign Metadata'!$C$5,"Sustainability Drive")} -> Before ModelYCampaign | I11: =C11-D11 -> -197
A12: 45516 | B12: Facebook | C12: 1534 | D12: 200 | E12: 307612 | F12: 6.01 | G12: 37903 | H12: {=_xlfn.IFS(A12<'Campaign Metadata'!$B$2,"Before CybertruckLaunch",'Engagement Summary'!A43<='Campaign Metadata'!$C$2,"CybertruckLaunch",A12<'Campaign Metadata'!$B$3,"Before ModelYCampaign",A12<='Campaign Metadata'!$C$3,"ModelYCampaign",A12<'Campaign Metadata'!$B$4,"Before FSDUpdate",A12<='Campaign Metadata'!$C$4,FSDUpdate,A12<'Campaign Metadata'!$B$5,Before SustainabilityDrive,A12<'Campaign Metadata'!$C$5,"Sustainability Drive")} -> Before ModelYCampaign | I12: =C12-D12 -> 1334
A13: 45523 | B13: Facebook | C13: 1078 | D13: 20 | E13: 183924 | F13: 8.84 | G13: 14203 | H13: {=_xlfn.IFS(A13<'Campaign Metadata'!$B$2,"Before CybertruckLaunch",'Engagement Summary'!A47<='Campaign Metadata'!$C$2,"CybertruckLaunch",A13<'Campaign Metadata'!$B$3,"Before ModelYCampaign",A13<='Campaign Metadata'!$C$3,"ModelYCampaign",A13<'Campaign Metadata'!$B$4,"Before FSDUpdate",A13<='Campaign Metadata'!$C$4,FSDUpdate,A13<'Campaign Metadata'!$B$5,Before SustainabilityDrive,A13<'Campaign Metadata'!$C$5,"Sustainability Drive")} -> Before ModelYCampaign | I13: =C13-D13 -> 1058
A14: 45530 | B14: Facebook | C14: 248 | D14: 211 | E14: 379380 | F14: 9.04 | G14: 26925 | H14: {=_xlfn.IFS(A14<'Campaign Metadata'!$B$2,"Before CybertruckLaunch",'Engagement Summary'!A51<='Campaign Metadata'!$C$2,"CybertruckLaunch",A14<'Campaign Metadata'!$B$3,"Before ModelYCampaign",A14<='Campaign Metadata'!$C$3,"ModelYCampaign",A14<'Campaign Metadata'!$B$4,"Before FSDUpdate",A14<='Campaign Metadata'!$C$4,FSDUpdate,A14<'Campaign Metadata'!$B$5,Before SustainabilityDrive,A14<'Campaign Metadata'!$C$5,"Sustainability Drive")} -> Before ModelYCampaign | I14: =C14-D14 -> 37
A15: 45537 | B15: Facebook | C15: 1520 | D15: 475 | E15: 496982 | F15: 6.41 | G15: 24384 | H15: {=_xlfn.IFS(A15<'Campaign Metadata'!$B$2,"Before CybertruckLaunch",'Engagement Summary'!A55<='Campaign Metadata'!$C$2,"CybertruckLaunch",A15<'Campaign Metadata'!$B$3,"Before ModelYCampaign",A15<='Campaign Metadata'!$C$3,"ModelYCampaign",A15<'Campaign Metadata'!$B$4,"Before FSDUpdate",A15<='Campaign Metadata'!$C$4,FSDUpdate,A15<'Campaign Metadata'!$B$5,Before SustainabilityDrive,A15<'Campaign Metadata'!$C$5,"Sustainability Drive")} -> CybertruckLaunch | I15: =C15-D15 -> 1045
A16: 45544 | B16: Facebook | C16: 1842 | D16: 414 | E16: 307524 | F16: 1.76 | G16: 40478 | H16: {=_xlfn.IFS(A16<'Campaign Metadata'!$B$2,"Before CybertruckLaunch",'Engagement Summary'!A59<='Campaign Metadata'!$C$2,"CybertruckLaunch",A16<'Campaign Metadata'!$B$3,"Before ModelYCampaign",A16<='Campaign Metadata'!$C$3,"ModelYCampaign",A16<'Campaign Metadata'!$B$4,"Before FSDUpdate",A16<='Campaign Metadata'!$C$4,FSDUpdate,A16<'Campaign Metadata'!$B$5,Before SustainabilityDrive,A16<'Campaign Metadata'!$C$5,"Sustainability Drive")} -> Before ModelYCampaign | I16: =C16-D16 -> 1428
A17: 45551 | B17: Facebook | C17: 443 | D17: 345 | E17: 474162 | F17: 9.2 | G17: 47462 | H17: {=_xlfn.IFS(A17<'Campaign Metadata'!$B$2,"Before CybertruckLaunch",'Engagement Summary'!A63<='Campaign Metadata'!$C$2,"CybertruckLaunch",A17<'Campaign Metadata'!$B$3,"Before ModelYCampaign",A17<='Campaign Metadata'!$C$3,"ModelYCampaign",A17<'Campaign Metadata'!$B$4,"Before FSDUpdate",A17<='Campaign Metadata'!$C$4,FSDUpdate,A17<'Campaign Metadata'!$B$5,Before SustainabilityDrive,A17<'Campaign Metadata'!$C$5,"Sustainability Drive")} -> Before ModelYCampaign | I17: =C17-D17 -> 98
A18: 45558 | B18: Facebook | C18: 198 | D18: 217 | E18: 239753 | F18: 7.36 | G18: 11901 | H18: {=_xlfn.IFS(A18<'Campaign Metadata'!$B$2,"Before CybertruckLaunch",'Engagement Summary'!A67<='Campaign Metadata'!$C$2,"CybertruckLaunch",A18<'Campaign Metadata'!$B$3,"Before ModelYCampaign",A18<='Campaign Metadata'!$C$3,"ModelYCampaign",A18<'Campaign Metadata'!$B$4,"Before FSDUpdate",A18<='Campaign Metadata'!$C$4,FSDUpdate,A18<'Campaign Metadata'!$B$5,Before SustainabilityDrive,A18<'Campaign Metadata'!$C$5,"Sustainability Drive")} -> Before ModelYCampaign | I18: =C18-D18 -> -19
A19: 45565 | B19: Facebook | C19: 250 | D19: 429 | E19: 453423 | F19: 1.77 | G19: 2315 | H19: {=_xlfn.IFS(A19<'Campaign Metadata'!$B$2,"Before CybertruckLaunch",'Engagement Summary'!A71<='Campaign Metadata'!$C$2,"CybertruckLaunch",A19<'Campaign Metadata'!$B$3,"Before ModelYCampaign",A19<='Campaign Metadata'!$C$3,"ModelYCampaign",A19<'Campaign Metadata'!$B$4,"Before FSDUpdate",A19<='Campaign Metadata'!$C$4,FSDUpdate,A19<'Campaign Metadata'!$B$5,Before SustainabilityDrive,A19<'Campaign Metadata'!$C$5,"Sustainability Drive")} -> Before ModelYCampaign | I19: =C19-D19 -> -179
A20: 45572 | B20: Facebook | C20: 1929 | D20: 267 | E20: 379363 | F20: 1.75 | G20: 43836 | H20: {=_xlfn.IFS(A20<'Campaign Metadata'!$B$2,"Before CybertruckLaunch",'Engagement Summary'!A75<='Campaign Metadata'!$C$2,"CybertruckLaunch",A20<'Campaign Metadata'!$B$3,"Before ModelYCampaign",A20<='Campaign Metadata'!$C$3,"ModelYCampaign",A20<'Campaign Metadata'!$B$4,"Before FSDUpdate",A20<='Campaign Metadata'!$C$4,FSDUpdate,A20<'Campaign Metadata'!$B$5,Before SustainabilityDrive,A20<'Campaign Metadata'!$C$5,"Sustainability Drive")} -> ModelYCampaign | I20: =C20-D20 -> 1662
A21: 45579 | B21: Facebook | C21: 643 | D21: 358 | E21: 157599 | F21: 3.88 | G21: 7285 | H21: {=_xlfn.IFS(A21<'Campaign Metadata'!$B$2,"Before CybertruckLaunch",'Engagement Summary'!A79<='Campaign Metadata'!$C$2,"CybertruckLaunch",A21<'Campaign Metadata'!$B$3,"Before ModelYCampaign",A21<='Campaign Metadata'!$C$3,"ModelYCampaign",A21<'Campaign Metadata'!$B$4,"Before FSDUpdate",A21<='Campaign Metadata'!$C$4,FSDUpdate,A21<'Campaign Metadata'!$B$5,Before SustainabilityDrive,A21<'Campaign Metadata'!$C$5,"Sustainability Drive")} -> ModelYCampaign | I21: =C21-D21 -> 285
A22: 45586 | B22: Facebook | C22: 508 | D22: 69 | E22: 23492 | F22: 3.16 | G22: 42824 | H22: {=_xlfn.IFS(A22<'Campaign Metadata'!$B$2,"Before CybertruckLaunch",'Engagement Summary'!A83<='Campaign Metadata'!$C$2,"CybertruckLaunch",A22<'Campaign Metadata'!$B$3,"Before ModelYCampaign",A22<='Campaign Metadata'!$C$3,"ModelYCampaign",A22<'Campaign Metadata'!$B$4,"Before FSDUpdate",A22<='Campaign Metadata'!$C$4,FSDUpdate,A22<'Campaign Metadata'!$B$5,Before SustainabilityDrive,A22<'Campaign Metadata'!$C$5,"Sustainability Drive")} -> ModelYCampaign | I22: =C22-D22 -> 439
A23: 45593 | B23: Facebook | C23: 859 | D23: 473 | E23: 209987 | F23: 4.46 | G23: 30214 | H23: {=_xlfn.IFS(A23<'Campaign Metadata'!$B$2,"Before CybertruckLaunch",'Engagement Summary'!A87<='Campaign Metadata'!$C$2,"CybertruckLaunch",A23<'Campaign Metadata'!$B$3,"Before ModelYCampaign",A23<='Campaign Metadata'!$C$3,"ModelYCampaign",A23<'Campaign Metadata'!$B$4,"Before FSDUpdate",A23<='Campaign Metadata'!$C$4,FSDUpdate,A23<'Campaign Metadata'!$B$5,Before SustainabilityDrive,A23<'Campaign Metadata'!$C$5,"Sustainability Drive")} -> ModelYCampaign | I23: =C23-D23 -> 386
A24: 45600 | B24: Facebook | C24: 947 | D24: 407 | E24: 319186 | F24: 3.32 | G24: 4996 | H24: {=_xlfn.IFS(A24<'Campaign Metadata'!$B$2,"Before CybertruckLaunch",'Engagement Summary'!A91<='Campaign Metadata'!$C$2,"CybertruckLaunch",A24<'Campaign Metadata'!$B$3,"Before ModelYCampaign",A24<='Campaign Metadata'!$C$3,"ModelYCampaign",A24<'Campaign Metadata'!$B$4,"Before FSDUpdate",A24<='Campaign Metadata'!$C$4,FSDUpdate,A24<'Campaign Metadata'!$B$5,Before SustainabilityDrive,A24<'Campaign Metadata'!$C$5,"Sustainability Drive")} -> Before FSDUpdate | I24: =C24-D24 -> 540
A25: 45607 | B25: Facebook | C25: 171 | D25: 277 | E25: 309483 | F25: 8.7 | G25: 38452 | H25: {=_xlfn.IFS(A25<'Campaign Metadata'!$B$2,"Before CybertruckLaunch",'Engagement Summary'!A95<='Campaign Metadata'!$C$2,"CybertruckLaunch",A25<'Campaign Metadata'!$B$3,"Before ModelYCampaign",A25<='Campaign Metadata'!$C$3,"ModelYCampaign",A25<'Campaign Metadata'!$B$4,"Before FSDUpdate",A25<='Campaign Metadata'!$C$4,FSDUpdate,A25<'Campaign Metadata'!$B$5,Before SustainabilityDrive,A25<'Campaign Metadata'!$C$5,"Sustainability Drive")} -> Before FSDUpdate | I25: =C25-D25 -> -106
A26: 45614 | B26: Facebook | C26: 513 | D26: 441 | E26: 338847 | F26: 2.68 | G26: 39997 | H26: {=_xlfn.IFS(A26<'Campaign Metadata'!$B$2,"Before CybertruckLaunch",'Engagement Summary'!A99<='Campaign Metadata'!$C$2,"CybertruckLaunch",A26<'Campaign Metadata'!$B$3,"Before ModelYCampaign",A26<='Campaign Metadata'!$C$3,"ModelYCampaign",A26<'Campaign Metadata'!$B$4,"Before FSDUpdate",A26<='Campaign Metadata'!$C$4,FSDUpdate,A26<'Campaign Metadata'!$B$5,Before SustainabilityDrive,A26<'Campaign Metadata'!$C$5,"Sustainability Drive")} -> Before FSDUpdate | I26: =C26-D26 -> 72
A27: 45621 | B27: Facebook | C27: 1710 | D27: 378 | E27: 336661 | F27: 6.2 | G27: 28498 | H27: {=_xlfn.IFS(A27<'Campaign Metadata'!$B$2,"Before CybertruckLaunch",'Engagement Summary'!A103<='Campaign Metadata'!$C$2,"CybertruckLaunch",A27<'Campaign Metadata'!$B$3,"Before ModelYCampaign",A27<='Campaign Metadata'!$C$3,"ModelYCampaign",A27<'Campaign Metadata'!$B$4,"Before FSDUpdate",A27<='Campaign Metadata'!$C$4,FSDUpdate,A27<'Campaign Metadata'!$B$5,Before SustainabilityDrive,A27<'Campaign Metadata'!$C$5,"Sustainability Drive")} -> CybertruckLaunch | I27: =C27-D27 -> 1332
A28: 45628 | B28: Facebook | C28: 1902 | D28: 196 | E28: 470269 | F28: 4.79 | G28: 26103 | H28: {=_xlfn.IFS(A28<'Campaign Metadata'!$B$2,"Before CybertruckLaunch",'Engagement Summary'!A107<='Campaign Metadata'!$C$2,"CybertruckLaunch",A28<'Campaign Metadata'!$B$3,"Before ModelYCampaign",A28<='Campaign Metadata'!$C$3,"ModelYCampaign",A28<'Campaign Metadata'!$B$4,"Before FSDUpdate",A28<='Campaign Metadata'!$C$4,FSDUpdate,A28<'Campaign Metadata'!$B$5,Before SustainabilityDrive,A28<'Campaign Metadata'!$C$5,"Sustainability Drive")} -> CybertruckLaunch | I28: =C28-D28 -> 1706
A29: 45635 | B29: Facebook | C29: 1514 | D29: 141 | E29: 35842 | F29: 7.47 | G29: 18601 | H29: {=_xlfn.IFS(A29<'Campaign Metadata'!$B$2,"Before CybertruckLaunch",'Engagement Summary'!A111<='Campaign Metadata'!$C$2,"CybertruckLaunch",A29<'Campaign Metadata'!$B$3,"Before ModelYCampaign",A29<='Campaign Metadata'!$C$3,"ModelYCampaign",A29<'Campaign Metadata'!$B$4,"Before FSDUpdate",A29<='Campaign Metadata'!$C$4,FSDUpdate,A29<'Campaign Metadata'!$B$5,Before SustainabilityDrive,A29<'Campaign Metadata'!$C$5,"Sustainability Drive")} -> Before FSDUpdate | I29: =C29-D29 -> 1373
A30: 45642 | B30: Facebook | C30: 1623 | D30: 246 | E30: 415815 | F30: 8.11 | G30: 18656 | H30: {=_xlfn.IFS(A30<'Campaign Metadata'!$B$2,"Before CybertruckLaunch",'Engagement Summary'!A115<='Campaign Metadata'!$C$2,"CybertruckLaunch",A30<'Campaign Metadata'!$B$3,"Before ModelYCampaign",A30<='Campaign Metadata'!$C$3,"ModelYCampaign",A30<'Campaign Metadata'!$B$4,"Before FSDUpdate",A30<='Campaign Metadata'!$C$4,FSDUpdate,A30<'Campaign Metadata'!$B$5,Before SustainabilityDrive,A30<'Campaign Metadata'!$C$5,"Sustainability Drive")} -> Before FSDUpdate | I30: =C30-D30 -> 1377
A31: 45649 | B31: Facebook | C31: 1155 | D31: 425 | E31: 93347 | F31: 2.02 | G31: 47502 | H31: {=_xlfn.IFS(A31<'Campaign Metadata'!$B$2,"Before CybertruckLaunch",'Engagement Summary'!A119<='Campaign Metadata'!$C$2,"CybertruckLaunch",A31<'Campaign Metadata'!$B$3,"Before ModelYCampaign",A31<='Campaign Metadata'!$C$3,"ModelYCampaign",A31<'Campaign Metadata'!$B$4,"Before FSDUpdate",A31<='Campaign Metadata'!$C$4,FSDUpdate,A31<'Campaign Metadata'!$B$5,Before SustainabilityDrive,A31<'Campaign Metadata'!$C$5,"Sustainability Drive")} -> Before FSDUpdate | I31: =C31-D31 -> 730
A32: 45656 | B32: Facebook | C32: 1980 | D32: 204 | E32: 379431 | F32: 3.09 | G32: 25140 | H32: {=_xlfn.IFS(A32<'Campaign Metadata'!$B$2,"Before CybertruckLaunch",'Engagement Summary'!A123<='Campaign Metadata'!$C$2,"CybertruckLaunch",A32<'Campaign Metadata'!$B$3,"Before ModelYCampaign",A32<='Campaign Metadata'!$C$3,"ModelYCampaign",A32<'Campaign Metadata'!$B$4,"Before FSDUpdate",A32<='Campaign Metadata'!$C$4,"FSDUpdate",A32<'Campaign Metadata'!$B$5,"Before SustainabilityDrive",A32<'Campaign Metadata'!$C$5,"Sustainability Drive")} -> FSDUpdate | I32: =C32-D32 -> 1776
A33: 45663 | B33: Facebook | C33: 816 | D33: 196 | E33: 95728 | F33: 8.2 | G33: 17951 | H33: {=_xlfn.IFS(A33<'Campaign Metadata'!$B$2,"Before CybertruckLaunch",'Engagement Summary'!A127<='Campaign Metadata'!$C$2,"CybertruckLaunch",A33<'Campaign Metadata'!$B$3,"Before ModelYCampaign",A33<='Campaign Metadata'!$C$3,"ModelYCampaign",A33<'Campaign Metadata'!$B$4,"Before FSDUpdate",A33<='Campaign Metadata'!$C$4,"FSDUpdate",A33<'Campaign Metadata'!$B$5,"Before SustainabilityDrive",A33<'Campaign Metadata'!$C$5,"Sustainability Drive")} -> FSDUpdate | I33: =C33-D33 -> 620
A34: 45670 | B34: Facebook | C34: 651 | D34: 353 | E34: 224699 | F34: 5.61 | G34: 45708 | H34: {=_xlfn.IFS(A34<'Campaign Metadata'!$B$2,"Before CybertruckLaunch",'Engagement Summary'!A131<='Campaign Metadata'!$C$2,"CybertruckLaunch",A34<'Campaign Metadata'!$B$3,"Before ModelYCampaign",A34<='Campaign Metadata'!$C$3,"ModelYCampaign",A34<'Campaign Metadata'!$B$4,"Before FSDUpdate",A34<='Campaign Metadata'!$C$4,"FSDUpdate",A34<'Campaign Metadata'!$B$5,"Before SustainabilityDrive",A34<'Campaign Metadata'!$C$5,"Sustainability Drive")} -> Before SustainabilityDrive | I34: =C34-D34 -> 298
A35: 45677 | B35: Facebook | C35: 663 | D35: 236 | E35: 479490 | F35: 4.51 | G35: 23853 | H35: {=_xlfn.IFS(A35<'Campaign Metadata'!$B$2,"Before CybertruckLaunch",'Engagement Summary'!A135<='Campaign Metadata'!$C$2,"CybertruckLaunch",A35<'Campaign Metadata'!$B$3,"Before ModelYCampaign",A35<='Campaign Metadata'!$C$3,"ModelYCampaign",A35<'Campaign Metadata'!$B$4,"Before FSDUpdate",A35<='Campaign Metadata'!$C$4,"FSDUpdate",A35<'Campaign Metadata'!$B$5,"Before SustainabilityDrive",A35<'Campaign Metadata'!$C$5,"Sustainability Drive")} -> Before SustainabilityDrive | I35: =C35-D35 -> 427
A36: 45684 | B36: Facebook | C36: 1249 | D36: 351 | E36: 321307 | F36: 6.37 | G36: 20560 | H36: {=_xlfn.IFS(A36<'Campaign Metadata'!$B$2,"Before CybertruckLaunch",'Engagement Summary'!A139<='Campaign Metadata'!$C$2,"CybertruckLaunch",A36<'Campaign Metadata'!$B$3,"Before ModelYCampaign",A36<='Campaign Metadata'!$C$3,"ModelYCampaign",A36<'Campaign Metadata'!$B$4,"Before FSDUpdate",A36<='Campaign Metadata'!$C$4,"FSDUpdate",A36<'Campaign Metadata'!$B$5,"Before SustainabilityDrive",A36<'Campaign Metadata'!$C$5,"Sustainability Drive")} -> Before SustainabilityDrive | I36: =C36-D36 -> 898
A37: 45691 | B37: Facebook | C37: 1159 | D37: 411 | E37: 135987 | F37: 8.7 | G37: 40323 | H37: {=_xlfn.IFS(A37<'Campaign Metadata'!$B$2,"Before CybertruckLaunch",'Engagement Summary'!A143<='Campaign Metadata'!$C$2,"CybertruckLaunch",A37<'Campaign Metadata'!$B$3,"Before ModelYCampaign",A37<='Campaign Metadata'!$C$3,"ModelYCampaign",A37<'Campaign Metadata'!$B$4,"Before FSDUpdate",A37<='Campaign Metadata'!$C$4,"FSDUpdate",A37<'Campaign Metadata'!$B$5,"Before SustainabilityDrive",A37<'Campaign Metadata'!$C$5,"Sustainability Drive")} -> Before SustainabilityDrive | I37: =C37-D37 -> 748
A38: 45698 | B38: Facebook | C38: 1294 | D38: 382 | E38: 309914 | F38: 8.03 | G38: 23489 | H38: {=_xlfn.IFS(A38<'Campaign Metadata'!$B$2,"Before CybertruckLaunch",'Engagement Summary'!A147<='Campaign Metadata'!$C$2,"CybertruckLaunch",A38<'Campaign Metadata'!$B$3,"Before ModelYCampaign",A38<='Campaign Metadata'!$C$3,"ModelYCampaign",A38<'Campaign Metadata'!$B$4,"Before FSDUpdate",A38<='Campaign Metadata'!$C$4,"FSDUpdate",A38<'Campaign Metadata'!$B$5,"Before SustainabilityDrive",A38<'Campaign Metadata'!$C$5,"Sustainability Drive")} -> Before SustainabilityDrive | I38: =C38-D38 -> 912
A39: 45705 | B39: Facebook | C39: 1895 | D39: 305 | E39: 104967 | F39: 3.85 | G39: 31853 | H39: {=_xlfn.IFS(A39<'Campaign Metadata'!$B$2,"Before CybertruckLaunch",'Engagement Summary'!A151<='Campaign Metadata'!$C$2,"CybertruckLaunch",A39<'Campaign Metadata'!$B$3,"Before ModelYCampaign",A39<='Campaign Metadata'!$C$3,"ModelYCampaign",A39<'Campaign Metadata'!$B$4,"Before FSDUpdate",A39<='Campaign Metadata'!$C$4,"FSDUpdate",A39<'Campaign Metadata'!$B$5,"Before SustainabilityDrive",A39<'Campaign Metadata'!$C$5,"Sustainability Drive")} -> Before SustainabilityDrive | I39: =C39-D39 -> 1590
A40: 45712 | B40: Facebook | C40: 1884 | D40: 177 | E40: 230448 | F40: 7.8 | G40: 22713 | H40: {=_xlfn.IFS(A40<'Campaign Metadata'!$B$2,"Before CybertruckLaunch",'Engagement Summary'!A155<='Campaign Metadata'!$C$2,"CybertruckLaunch",A40<'Campaign Metadata'!$B$3,"Before ModelYCampaign",A40<='Campaign Metadata'!$C$3,"ModelYCampaign",A40<'Campaign Metadata'!$B$4,"Before FSDUpdate",A40<='Campaign Metadata'!$C$4,"FSDUpdate",A40<'Campaign Metadata'!$B$5,"Before SustainabilityDrive",A40<'Campaign Metadata'!$C$5,"Sustainability Drive")} -> CybertruckLaunch | I40: =C40-D40 -> 1707
...

Sheet Campaign Metadata
A1: Campaign_Name | B1: Start_Date | C1: End_Date | D1: Objective | E1: Total_Budget | F1: Target_Platforms | G1: Primary_Hashtags
A2: CybertruckLaunch | B2: 45458 | C2: 45488 | D2: Product Awareness | E2: 150000 | F2: Instagram,Facebook | G2: #EVRevolution,#TeslaCoInnovation
A3: ModelYCampaign | B3: 45566 | C3: 45596 | D3: Customer Engagement | E3: 200000 | F3: Instagram,YouTube | G3: #AnytimeIsTeslaTime,
A4: FSDUpdate | B4: 45651 | C4: 45667 | D4: Vehicle Launch | E4: 250000 | F4: Facebook,Twitter | G4: #SmoothLikeNitroTesla
A5: SustainabilityDrive | B5: 45717 | C5: 45747 | D5: Community Growth | E5: 180000 | F5: Instagram,Twitter | G5: #BetterWithTesla,#FutureOfDriving

Sheet Engagement Analysis
A3: Row Labels | B3: Average of Clicks | C3: Average of Engagement Rate | D3: Count of Hashtags Used
A4: #AnytimeIsTeslaTime | B4: 161.2 | C4: 0.11636074 | D4: 15
A5: #TeslaCoInnovation | B5: 158.65421 | C5: 0.14515321 | D5: 107
A6: #EVRevolution | B6: 151.52941 | C6: 0.15386133 | D6: 102
A7: #FutureOfDriving | B7: 144.03883 | C7: 0.14123247 | D7: 103
A8: #BetterWithTesla | B8: 114.85714 | C8: 0.12589595 | D8: 7
A9: #SmoothLikeNitroTesla | B9: 111.8 | C9: 0.11481754 | D9: 5
B12: Column Labels
B13: Facebook | F13: Instagram | J13: Twitter | N13: YouTube
A14: Row Labels | B14: Sum of Likes | C14: Sum of Shares | D14: Sum of Comments | E14: Sum of Total | F14: Sum of Likes | G14: Sum of Shares | H14: Sum of Comments | I14: Sum of Total | J14: Sum of Likes | K14: Sum of Shares | L14: Sum of Comments | M14: Sum of Total | N14: Sum of Likes | O14: Sum of Shares | P14: Sum of Comments | Q14: Sum of Total
A15: Carousel | B15: 44476 | C15: 7400 | D15: 4589 | E15: 56465 | F15: 43948 | G15: 6975 | H15: 3890 | I15: 54813 | J15: 48649 | K15: 5791 | L15: 3607 | M15: 58047 | N15: 24926 | O15: 6305 | P15: 2422 | Q15: 33653
A16: Image | B16: 71602 | C16: 12904 | D16: 6495 | E16: 91001 | F16: 34202 | G16: 5286 | H16: 2655 | I16: 42143 | J16: 43761 | K16: 7110 | L16: 5125 | M16: 55996 | N16: 23903 | O16: 4310 | P16: 2077 | Q16: 30290
A17: Reel | B17: 36368 | C17: 5964 | D17: 3353 | E17: 45685 | F17: 32148 | G17: 8110 | H17: 3386 | I17: 43644 | J17: 27029 | K17: 4550 | L17: 1913 | M17: 33492 | N17: 32400 | O17: 4577 | P17: 2668 | Q17: 39645
A18: Story | B18: 29405 | C18: 4950 | D18: 3223 | E18: 37578 | F18: 42649 | G18: 10049 | H18: 3846 | I18: 56544 | J18: 20466 | K18: 5090 | L18: 3026 | M18: 28582 | N18: 31968 | O18: 3866 | P18: 2012 | Q18: 37846
A19: Text | B19: 31963 | C19: 4792 | D19: 3377 | E19: 40132 | F19: 25567 | G19: 5112 | H19: 1946 | I19: 32625 | J19: 31899 | K19: 4861 | L19: 3910 | M19: 40670 | N19: 27067 | O19: 3928 | P19: 1052 | Q19: 32047
A20: Video | B20: 28947 | C20: 3171 | D20: 2263 | E20: 34381 | F20: 25770 | G20: 5912 | H20: 2128 | I20: 33810 | J20: 29593 | K20: 6326 | L20: 3299 | M20: 39218 | N20: 31285 | O20: 5586 | P20: 2589 | Q20: 39460
A23: Average of Engagement Rate | B23: Column Labels
A24: Row Labels | B24: Facebook | C24: Instagram | D24: Twitter | E24: YouTube | F24: Grand Total
A25: Carousel | B25: 0.1182059 | C25: 0.1443986 | D25: 0.15972488 | E25: 0.17416554 | F25: 0.1481492
A26: Image | B26: 0.11892683 | C26: 0.14929862 | D26: 0.14756648 | E26: 0.15035568 | F26: 0.13687494
A27: Reel | B27: 0.10810248 | C27: 0.26004033 | D27: 0.12428082 | E27: 0.11688584 | F27: 0.15615682
A28: Story | B28: 0.15898978 | C28: 0.24558274 | D28: 0.18859717 | E28: 0.09496533 | F28: 0.18425775
A29: Text | B29: 0.10743951 | C29: 0.12920449 | D29: 0.12088973 | E29: 0.11459218 | F29: 0.11750674
A30: Video | B30: 0.12899654 | C30: 0.20623961 | D30: 0.11980877 | E30: 0.12968338 | F30: 0.14814844
A31: Grand Total | B31: 0.1219729 | C31: 0.19329258 | D31: 0.14368407 | E31: 0.13118494 | F31: 0.14828272

Sheet Video Link
A4: Link | B4: https://drive.google.com/file/d/11lhKxGlFVVRo0KJs1vJ4y3b64r5tW5op/view?usp=sharing

Sheet Platform Analysis
A3: Row Labels | B3: Sum of New_Followers | C3: Sum of Unfollows | D3: Sum of Growth
A4: Facebook | B4: 50862 | C4: 15305 | D4: 35557
A5: Instagram | B5: 58311 | C5: 10307 | D5: 48004
A6: Twitter | B6: 53484 | C6: 12307 | D6: 41177
A7: YouTube | B7: 47471 | C7: 12104 | D7: 35367
A10: Row Labels | B10: Average of Engagement_Rate | C10: Average of Ad_Spend
A11: Facebook | B11: 5.6486 | C11: 27590.78
A12: Instagram | B12: 5.7156 | C12: 23287.46
A13: Twitter | B13: 5.6558 | C13: 21207.14
A14: YouTube | B14: 5.5588 | C14: 24572.94

Sheet Campaign Effectiveness
A3: Row Labels | B3: Average of Impressions | C3: Average of Likes | D3: Average of Clicks | E3: Sum of Impressions | F3: Sum of Likes | G3: Sum of Clicks
A4: CybertruckLaunch | B4: 38464 | C4: 2891.5208 | D4: 134.04167 | E4: 1846272 | F4: 138793 | G4: 6434
A5: FSDUpdate | B5: 33821.687 | C5: 2736.5075 | D5: 149.73134 | E5: 2266053 | F5: 183346 | G5: 10032
A6: ModelYCampaign | B6: 34247.517 | C6: 2754.8793 | D6: 170.2069 | E6: 1986356 | F6: 159783 | G6: 9872
A7: SustainabilityDrive | B7: 34716.394 | C7: 2646.6056 | D7: 150.5493 | E7: 2464864 | F7: 187909 | G7: 10689
A10: Row Labels | B10: Average of Engagement_Rate | C10: Average of Follower Growth | E10: Row Labels | F10: Sum of Engagement_Rate | G10: Sum of Ad_Spend
A11: Before CybertruckLaunch | B11: 6.115 | C11: 962.25 | E11: CybertruckLaunch | F11: 131.76 | G11: 558230
A12: Before FSDUpdate | B12: 5.5658333 | C12: 789.25 | E12: FSDUpdate | F12: 38.06 | G12: 151428
A13: Before ModelYCampaign | B13: 5.8955172 | C13: 634.96552 | E13: ModelYCampaign | F13: 83.32 | G13: 447611
A14: Before SustainabilityDrive | B14: 5.85 | C14: 980.75 | E14: Sustainability Drive | F14: 90.7 | G14: 315597
A15: CybertruckLaunch | B15: 6.337 | C15: 1461.7 | E15: Grand Total | F15: 343.84 | G15: 1472866
A16: FSDUpdate | B16: 4.5875 | C16: 1266
A17: ModelYCampaign | B17: 5.09375 | C17: 838.25
A18: Sustainability Drive | B18: 6.2714286 | C18: 533.14286

Sheet Follower Retention
A3: Row Labels | B3: Sum of Follower Growth
A4: 03/06/24 - 09/06/24 | B4: 3554
A5: 10/06/24 - 16/06/24 | B5: 2980
A6: 17/06/24 - 23/06/24 | B6: 3907
A7: 24/06/24 - 30/06/24 | B7: 3011
A8: 01/07/24 - 07/07/24 | B8: 1293
A9: 08/07/24 - 14/07/24 | B9: 3042
A10: 15/07/24 - 21/07/24 | B10: 2270
A11: 22/07/24 - 28/07/24 | B11: 2753
A12: 29/07/24 - 04/08/24 | B12: 2193
A13: 05/08/24 - 11/08/24 | B13: 802
A14: 12/08/24 - 18/08/24 | B14: 3728
A15: 19/08/24 - 25/08/24 | B15: 2989
... A26: 04/11/24 - 10/11/24 | B26: 4584
A27: 11/11/24 - 17/11/24 | B27: 2295 | D27: Row Labels | E27: Average of Unfollows
A28: 18/11/24 - 24/11/24 | B28: 528 | D28: CybertruckLaunch | E28: 237.85714
A29: 25/11/24 - 01/12/24 | B29: 4008 | D29: FSDUpdate | E29: 167.625
A30: 02/12/24 - 08/12/24 | B30: 4795 | D30: ModelYCampaign | E30: 214.125
A31: 09/12/24 - 15/12/24 | B31: 4792 | D31: Sustainability Drive | E31: 194.8
A32: 16/12/24 - 22/12/24 | B32: 5044 | D32: Grand Total | E32: 211.4
A33: 23/12/24 - 29/12/24 | B33: 3914
A34: 30/12/24 - 05/01/25 | B34: 6530
A35: 06/01/25 - 12/01/25 | B35: 3557
A36: 13/01/25 - 19/01/25 | B36: 2777
A37: 20/01/25 - 26/01/25 | B37: 3614
A38: 27/01/25 - 02/02/25 | B38: 3383
A39: 03/02/25 - 09/02/25 | B39: 2194
A40: 10/02/25 - 16/02/25 | B40: 5281
A41: 17/02/25 - 23/02/25 | B41: 3693
A42: 24/02/25 - 02/03/25 | B42: 4806
A43: 03/03/25 - 09/03/25 | B43: 2410
A44: 10/03/25 - 16/03/25 | B44: 3712
... A54: Grand Total | B54: 160105
